{
  "timestamp": "2025-06-25T10:00:30.433948",
  "summary": {
    "total_tests": 130,
    "total_failures": 9,
    "total_errors": 23,
    "total_skipped": 0,
    "success_rate": 75.38461538461539,
    "execution_time": 61.216896057128906,
    "passed": false
  },
  "modules": {
    "test_sim_manager": {
      "tests_run": 25,
      "failures": 0,
      "errors": 0,
      "skipped": 0,
      "success_rate": 100.0,
      "execution_time": 10.022788047790527,
      "failure_details": [],
      "error_details": []
    },
    "test_ip_manager": {
      "tests_run": 31,
      "failures": 2,
      "errors": 2,
      "skipped": 0,
      "success_rate": 87.09677419354838,
      "execution_time": 40.192842960357666,
      "failure_details": [
        {
          "test": "test_ip_range_scanning (test_ip_manager.TestIPManager.test_ip_range_scanning)",
          "traceback": "Traceback (most recent call last):\n  File \"/Users/bill/dev/sdk-samples/SimSelector/tests/test_ip_manager.py\", line 427, in test_ip_range_scanning\n    self.assertIn(\"192.168.1.10\", active_ips)\nAssertionError: '192.168.1.10' not found in []\n"
        },
        {
          "test": "test_ping_command_failure (test_ip_manager.TestIPManagerEdgeCases.test_ping_command_failure)",
          "traceback": "Traceback (most recent call last):\n  File \"/Users/bill/dev/sdk-samples/SimSelector/tests/test_ip_manager.py\", line 536, in test_ping_command_failure\n    self.assertFalse(available)\nAssertionError: True is not false\n"
        }
      ],
      "error_details": [
        {
          "test": "test_is_ip_available_function (test_ip_manager.TestIPManagerUtilityFunctions.test_is_ip_available_function)",
          "traceback": "Traceback (most recent call last):\n  File \"/Users/bill/dev/sdk-samples/SimSelector/tests/test_ip_manager.py\", line 478, in test_is_ip_available_function\n    result = is_ip_available(\"192.168.1.10\", client)\n             ^^^^^^^^^^^^^^^^^^^^^^^^^^^^^^^^^^^^^^^\n  File \"/Users/bill/dev/sdk-samples/SimSelector/ip_manager.py\", line 1194, in is_ip_available\n    return len(conflicts) == 0\n          ^^^^^^^^^^^^^^\nTypeError: object of type 'Mock' has no len()\n"
        },
        {
          "test": "test_validate_ip_configuration_function (test_ip_manager.TestIPManagerUtilityFunctions.test_validate_ip_configuration_function)",
          "traceback": "Traceback (most recent call last):\n  File \"/Users/bill/dev/sdk-samples/SimSelector/tests/test_ip_manager.py\", line 463, in test_validate_ip_configuration_function\n    result = validate_ip_configuration(\"192.168.1.10\", client)\n             ^^^^^^^^^^^^^^^^^^^^^^^^^^^^^^^^^^^^^^^^^^^^^^^^^\nTypeError: validate_ip_configuration() missing 1 required positional argument: 'gateway'\n"
        }
      ]
    },
    "test_traffic_validator": {
      "tests_run": 34,
      "failures": 4,
      "errors": 17,
      "skipped": 0,
      "success_rate": 38.23529411764706,
      "execution_time": 10.185713768005371,
      "failure_details": [
        {
          "test": "test_quality_of_service_monitoring (test_traffic_validator.TestTrafficValidator.test_quality_of_service_monitoring)",
          "traceback": "Traceback (most recent call last):\n  File \"/Users/bill/dev/sdk-samples/SimSelector/tests/test_traffic_validator.py\", line 261, in test_quality_of_service_monitoring\n    self.assertIn(\"interfaces\", qos_status)\nAssertionError: 'interfaces' not found in {'success': True, 'qos_data': {'enp1s0': {'priority_queues': [{'priority': 'high', 'packets': 1000, 'bytes': 1048576, 'drops': 0}, {'priority': 'normal', 'packets': 5000, 'bytes': 5242880, 'drops': 2}, {'priority': 'low', 'packets': 2000, 'bytes': 2097152, 'drops': 5}]}}, 'timestamp': 1750863619.785086}\n"
        },
        {
          "test": "test_high_latency_scenarios (test_traffic_validator.TestTrafficValidatorEdgeCases.test_high_latency_scenarios)",
          "traceback": "Traceback (most recent call last):\n  File \"/Users/bill/dev/sdk-samples/SimSelector/tests/test_traffic_validator.py\", line 567, in test_high_latency_scenarios\n    self.assertIn(\"warning\", result)\nAssertionError: 'warning' not found in {'success': True, 'latency': 1500.0, 'host': '8.8.8.8', 'output': '64 bytes from 8.8.8.8: icmp_seq=1 time=1500.0 ms'}\n"
        },
        {
          "test": "test_malformed_speedtest_output (test_traffic_validator.TestTrafficValidatorEdgeCases.test_malformed_speedtest_output)",
          "traceback": "Traceback (most recent call last):\n  File \"/Users/bill/dev/sdk-samples/SimSelector/tests/test_traffic_validator.py\", line 537, in test_malformed_speedtest_output\n    self.assertIn(\"parse\", result[\"error\"].lower())\nAssertionError: 'parse' not found in 'invalid speed test output format'\n"
        },
        {
          "test": "test_speedtest_command_not_found (test_traffic_validator.TestTrafficValidatorEdgeCases.test_speedtest_command_not_found)",
          "traceback": "Traceback (most recent call last):\n  File \"/Users/bill/dev/sdk-samples/SimSelector/tests/test_traffic_validator.py\", line 522, in test_speedtest_command_not_found\n    self.assertIn(\"command not found\", result[\"error\"].lower())\nAssertionError: 'command not found' not found in 'speedtest-cli not found'\n"
        }
      ],
      "error_details": [
        {
          "test": "test_bandwidth_trending (test_traffic_validator.TestTrafficValidator.test_bandwidth_trending)",
          "traceback": "Traceback (most recent call last):\n  File \"/Users/bill/dev/sdk-samples/SimSelector/tests/test_traffic_validator.py\", line 415, in test_bandwidth_trending\n    trend = self.validator.analyze_bandwidth_trend(historical_data)\n            ^^^^^^^^^^^^^^^^^^^^^^^^^^^^^^^^^^^^^^\nAttributeError: 'TrafficValidator' object has no attribute 'analyze_bandwidth_trend'\n"
        },
        {
          "test": "test_dns_resolution_test (test_traffic_validator.TestTrafficValidator.test_dns_resolution_test)",
          "traceback": "Traceback (most recent call last):\n  File \"/Users/bill/dev/sdk-samples/SimSelector/tests/test_traffic_validator.py\", line 368, in test_dns_resolution_test\n    result = self.validator.test_dns_resolution()\n             ^^^^^^^^^^^^^^^^^^^^^^^^^^^^^^^^^^\nAttributeError: 'TrafficValidator' object has no attribute 'test_dns_resolution'\n"
        },
        {
          "test": "test_interface_monitoring (test_traffic_validator.TestTrafficValidator.test_interface_monitoring)",
          "traceback": "Traceback (most recent call last):\n  File \"/Users/bill/dev/sdk-samples/SimSelector/tests/test_traffic_validator.py\", line 356, in test_interface_monitoring\n    interfaces = self.validator.monitor_interfaces()\n                 ^^^^^^^^^^^^^^^^^^^^^^^^^^^^^^^^^\nAttributeError: 'TrafficValidator' object has no attribute 'monitor_interfaces'\n"
        },
        {
          "test": "test_latency_analysis (test_traffic_validator.TestTrafficValidator.test_latency_analysis)",
          "traceback": "Traceback (most recent call last):\n  File \"/Users/bill/dev/sdk-samples/SimSelector/tests/test_traffic_validator.py\", line 299, in test_latency_analysis\n    analysis = self.validator.analyze_latency(15.0)\n               ^^^^^^^^^^^^^^^^^^^^^^^^^^^^^^\nAttributeError: 'TrafficValidator' object has no attribute 'analyze_latency'\n"
        },
        {
          "test": "test_network_test_comprehensive (test_traffic_validator.TestTrafficValidator.test_network_test_comprehensive)",
          "traceback": "Traceback (most recent call last):\n  File \"/Users/bill/dev/sdk-samples/SimSelector/tests/test_traffic_validator.py\", line 277, in test_network_test_comprehensive\n    result = self.validator.run_comprehensive_test()\n             ^^^^^^^^^^^^^^^^^^^^^^^^^^^^^^^^^^^^^\nAttributeError: 'TrafficValidator' object has no attribute 'run_comprehensive_test'\n"
        },
        {
          "test": "test_network_test_failure_scenarios (test_traffic_validator.TestTrafficValidator.test_network_test_failure_scenarios)",
          "traceback": "Traceback (most recent call last):\n  File \"/Users/bill/dev/sdk-samples/SimSelector/tests/test_traffic_validator.py\", line 291, in test_network_test_failure_scenarios\n    result = self.validator.run_comprehensive_test()\n             ^^^^^^^^^^^^^^^^^^^^^^^^^^^^^^^^^^^^^\nAttributeError: 'TrafficValidator' object has no attribute 'run_comprehensive_test'\n"
        },
        {
          "test": "test_network_topology_discovery (test_traffic_validator.TestTrafficValidator.test_network_topology_discovery)",
          "traceback": "Traceback (most recent call last):\n  File \"/Users/bill/dev/sdk-samples/SimSelector/tests/test_traffic_validator.py\", line 432, in test_network_topology_discovery\n    topology = self.validator.discover_network_topology()\n               ^^^^^^^^^^^^^^^^^^^^^^^^^^^^^^^^^^^^^^^^\nAttributeError: 'TrafficValidator' object has no attribute 'discover_network_topology'\n"
        },
        {
          "test": "test_packet_loss_detection (test_traffic_validator.TestTrafficValidator.test_packet_loss_detection)",
          "traceback": "Traceback (most recent call last):\n  File \"/Users/bill/dev/sdk-samples/SimSelector/tests/test_traffic_validator.py\", line 318, in test_packet_loss_detection\n    result = self.validator.test_packet_loss()\n             ^^^^^^^^^^^^^^^^^^^^^^^^^^^^^^^\nAttributeError: 'TrafficValidator' object has no attribute 'test_packet_loss'\n"
        },
        {
          "test": "test_traffic_analysis_patterns (test_traffic_validator.TestTrafficValidator.test_traffic_analysis_patterns)",
          "traceback": "Traceback (most recent call last):\n  File \"/Users/bill/dev/sdk-samples/SimSelector/tests/test_traffic_validator.py\", line 333, in test_traffic_analysis_patterns\n    analysis = self.validator.analyze_traffic_patterns(traffic_data)\n               ^^^^^^^^^^^^^^^^^^^^^^^^^^^^^^^^^^^^^^^\nAttributeError: 'TrafficValidator' object has no attribute 'analyze_traffic_patterns'\n"
        },
        {
          "test": "test_traffic_validator_status (test_traffic_validator.TestTrafficValidator.test_traffic_validator_status)",
          "traceback": "Traceback (most recent call last):\n  File \"/Users/bill/dev/sdk-samples/SimSelector/tests/test_traffic_validator.py\", line 398, in test_traffic_validator_status\n    status = self.validator.get_status()\n             ^^^^^^^^^^^^^^^^^^^^^^^^^\nAttributeError: 'TrafficValidator' object has no attribute 'get_status'\n"
        },
        {
          "test": "test_wan_failover_testing (test_traffic_validator.TestTrafficValidator.test_wan_failover_testing)",
          "traceback": "Traceback (most recent call last):\n  File \"/Users/bill/dev/sdk-samples/SimSelector/tests/test_traffic_validator.py\", line 384, in test_wan_failover_testing\n    failover_status = self.validator.test_wan_failover()\n                      ^^^^^^^^^^^^^^^^^^^^^^^^^^^^^^^^\nAttributeError: 'TrafficValidator' object has no attribute 'test_wan_failover'\n"
        },
        {
          "test": "test_concurrent_test_execution (test_traffic_validator.TestTrafficValidatorEdgeCases.test_concurrent_test_execution)",
          "traceback": "Traceback (most recent call last):\n  File \"/Users/bill/dev/sdk-samples/SimSelector/tests/test_traffic_validator.py\", line 593, in test_concurrent_test_execution\n    result = self.validator.run_comprehensive_test()\n             ^^^^^^^^^^^^^^^^^^^^^^^^^^^^^^^^^^^^^\nAttributeError: 'TrafficValidator' object has no attribute 'run_comprehensive_test'\n"
        },
        {
          "test": "test_memory_usage_monitoring (test_traffic_validator.TestTrafficValidatorEdgeCases.test_memory_usage_monitoring)",
          "traceback": "Traceback (most recent call last):\n  File \"/Users/bill/dev/sdk-samples/SimSelector/tests/test_traffic_validator.py\", line 619, in test_memory_usage_monitoring\n    status = self.validator.get_status()\n             ^^^^^^^^^^^^^^^^^^^^^^^^^\nAttributeError: 'TrafficValidator' object has no attribute 'get_status'\n"
        },
        {
          "test": "test_network_interface_down (test_traffic_validator.TestTrafficValidatorEdgeCases.test_network_interface_down)",
          "traceback": "Traceback (most recent call last):\n  File \"/Users/bill/dev/sdk-samples/SimSelector/tests/test_traffic_validator.py\", line 548, in test_network_interface_down\n    interfaces = self.validator.monitor_interfaces()\n                 ^^^^^^^^^^^^^^^^^^^^^^^^^^^^^^^^^\nAttributeError: 'TrafficValidator' object has no attribute 'monitor_interfaces'\n"
        },
        {
          "test": "test_traffic_validator_without_client (test_traffic_validator.TestTrafficValidatorEdgeCases.test_traffic_validator_without_client)",
          "traceback": "Traceback (most recent call last):\n  File \"/Users/bill/dev/sdk-samples/SimSelector/tests/test_traffic_validator.py\", line 605, in test_traffic_validator_without_client\n    result = validator.monitor_interfaces()\n             ^^^^^^^^^^^^^^^^^^^^^^^^^^^^\nAttributeError: 'TrafficValidator' object has no attribute 'monitor_interfaces'\n"
        },
        {
          "test": "test_run_speed_test_function (test_traffic_validator.TestTrafficValidatorUtilityFunctions.test_run_speed_test_function)",
          "traceback": "Traceback (most recent call last):\n  File \"/Users/bill/dev/sdk-samples/SimSelector/tests/test_traffic_validator.py\", line 487, in test_run_speed_test_function\n    self.assertTrue(result[\"success\"])\n                    ~~~~~~^^^^^^^^^^^\nTypeError: 'NetworkTest' object is not subscriptable\n"
        },
        {
          "test": "test_validate_network_connectivity_function (test_traffic_validator.TestTrafficValidatorUtilityFunctions.test_validate_network_connectivity_function)",
          "traceback": "Traceback (most recent call last):\n  File \"/Users/bill/dev/sdk-samples/SimSelector/tests/test_traffic_validator.py\", line 472, in test_validate_network_connectivity_function\n    self.assertTrue(result[\"success\"])\n                    ~~~~~~^^^^^^^^^^^\nTypeError: 'NetworkTest' object is not subscriptable\n"
        }
      ]
    },
    "test_error_handler": {
      "tests_run": 25,
      "failures": 1,
      "errors": 0,
      "skipped": 0,
      "success_rate": 96.0,
      "execution_time": 0.16386795043945312,
      "failure_details": [
        {
          "test": "test_error_id_uniqueness (test_error_handler.TestSimSelectorError.test_error_id_uniqueness)",
          "traceback": "Traceback (most recent call last):\n  File \"/Users/bill/dev/sdk-samples/SimSelector/tests/test_error_handler.py\", line 154, in test_error_id_uniqueness\n    self.assertNotEqual(error1.error_id, error2.error_id)\nAssertionError: 'UNKNOWN_1750863630' == 'UNKNOWN_1750863630'\n"
        }
      ],
      "error_details": []
    },
    "test_dashboard_server": {
      "tests_run": 9,
      "failures": 2,
      "errors": 4,
      "skipped": 0,
      "success_rate": 33.33333333333333,
      "execution_time": 0.020056724548339844,
      "failure_details": [
        {
          "test": "test_error_handling (test_dashboard_server.TestDashboardServer.test_error_handling)",
          "traceback": "Traceback (most recent call last):\n  File \"/Users/bill/dev/sdk-samples/SimSelector/phase_manager.py\", line 105, in _load_phase_state\n    self._log(f\"Loaded phase state: {Phase.get_name(self._current_phase)}\")\n  File \"/Users/bill/dev/sdk-samples/SimSelector/phase_manager.py\", line 88, in _log\n    self.client.log(f\"PHASE [{level}] {message}\")\n    ^^^^^^^^^^^^^^^\nAttributeError: 'str' object has no attribute 'log'\n\nDuring handling of the above exception, another exception occurred:\n\nTraceback (most recent call last):\n  File \"/Users/bill/dev/sdk-samples/SimSelector/tests/test_dashboard_server.py\", line 179, in test_error_handling\n    server = DashboardServer('invalid_host', -1)\n             ^^^^^^^^^^^^^^^^^^^^^^^^^^^^^^^^^^^\n  File \"/Users/bill/dev/sdk-samples/SimSelector/dashboard_server.py\", line 1342, in __init__\n    self.phase_manager = get_phase_manager(client)\n                         ^^^^^^^^^^^^^^^^^^^^^^^^^\n  File \"/Users/bill/dev/sdk-samples/SimSelector/phase_manager.py\", line 513, in get_phase_manager\n    _phase_manager = PhaseManager(client)\n                     ^^^^^^^^^^^^^^^^^^^^\n  File \"/Users/bill/dev/sdk-samples/SimSelector/phase_manager.py\", line 83, in __init__\n    self._load_phase_state()\n  File \"/Users/bill/dev/sdk-samples/SimSelector/phase_manager.py\", line 112, in _load_phase_state\n    self._log(f\"Error loading phase state: {str(e)}\", \"ERROR\")\n  File \"/Users/bill/dev/sdk-samples/SimSelector/phase_manager.py\", line 88, in _log\n    self.client.log(f\"PHASE [{level}] {message}\")\n    ^^^^^^^^^^^^^^^\nAttributeError: 'str' object has no attribute 'log'\n\nDuring handling of the above exception, another exception occurred:\n\nTraceback (most recent call last):\n  File \"/Users/bill/dev/sdk-samples/SimSelector/tests/test_dashboard_server.py\", line 184, in test_error_handling\n    self.fail(f\"Server creation should handle invalid parameters: {e}\")\nAssertionError: Server creation should handle invalid parameters: 'str' object has no attribute 'log'\n"
        },
        {
          "test": "test_server_initialization (test_dashboard_server.TestDashboardServer.test_server_initialization)",
          "traceback": "Traceback (most recent call last):\n  File \"/Users/bill/dev/sdk-samples/SimSelector/tests/test_dashboard_server.py\", line 115, in test_server_initialization\n    self.assertEqual(server.host, '127.0.0.1')\nAssertionError: '0.0.0.0' != '127.0.0.1'\n- 0.0.0.0\n+ 127.0.0.1\n\n"
        }
      ],
      "error_details": [
        {
          "test": "test_concurrent_requests (test_dashboard_server.TestDashboardServer.test_concurrent_requests)",
          "traceback": "Traceback (most recent call last):\n  File \"/Users/bill/dev/sdk-samples/SimSelector/phase_manager.py\", line 105, in _load_phase_state\n    self._log(f\"Loaded phase state: {Phase.get_name(self._current_phase)}\")\n  File \"/Users/bill/dev/sdk-samples/SimSelector/phase_manager.py\", line 88, in _log\n    self.client.log(f\"PHASE [{level}] {message}\")\n    ^^^^^^^^^^^^^^^\nAttributeError: 'str' object has no attribute 'log'\n\nDuring handling of the above exception, another exception occurred:\n\nTraceback (most recent call last):\n  File \"/Users/bill/dev/sdk-samples/SimSelector/tests/test_dashboard_server.py\", line 238, in test_concurrent_requests\n    server = DashboardServer(self.test_host, self.test_port)\n             ^^^^^^^^^^^^^^^^^^^^^^^^^^^^^^^^^^^^^^^^^^^^^^^\n  File \"/Users/bill/dev/sdk-samples/SimSelector/dashboard_server.py\", line 1342, in __init__\n    self.phase_manager = get_phase_manager(client)\n                         ^^^^^^^^^^^^^^^^^^^^^^^^^\n  File \"/Users/bill/dev/sdk-samples/SimSelector/phase_manager.py\", line 513, in get_phase_manager\n    _phase_manager = PhaseManager(client)\n                     ^^^^^^^^^^^^^^^^^^^^\n  File \"/Users/bill/dev/sdk-samples/SimSelector/phase_manager.py\", line 83, in __init__\n    self._load_phase_state()\n  File \"/Users/bill/dev/sdk-samples/SimSelector/phase_manager.py\", line 112, in _load_phase_state\n    self._log(f\"Error loading phase state: {str(e)}\", \"ERROR\")\n  File \"/Users/bill/dev/sdk-samples/SimSelector/phase_manager.py\", line 88, in _log\n    self.client.log(f\"PHASE [{level}] {message}\")\n    ^^^^^^^^^^^^^^^\nAttributeError: 'str' object has no attribute 'log'\n"
        },
        {
          "test": "test_dashboard_data_rendering (test_dashboard_server.TestDashboardServer.test_dashboard_data_rendering)",
          "traceback": "Traceback (most recent call last):\n  File \"/Users/bill/dev/sdk-samples/SimSelector/phase_manager.py\", line 105, in _load_phase_state\n    self._log(f\"Loaded phase state: {Phase.get_name(self._current_phase)}\")\n  File \"/Users/bill/dev/sdk-samples/SimSelector/phase_manager.py\", line 88, in _log\n    self.client.log(f\"PHASE [{level}] {message}\")\n    ^^^^^^^^^^^^^^^\nAttributeError: 'str' object has no attribute 'log'\n\nDuring handling of the above exception, another exception occurred:\n\nTraceback (most recent call last):\n  File \"/Users/bill/dev/sdk-samples/SimSelector/tests/test_dashboard_server.py\", line 294, in test_dashboard_data_rendering\n    server = DashboardServer(self.test_host, self.test_port)\n             ^^^^^^^^^^^^^^^^^^^^^^^^^^^^^^^^^^^^^^^^^^^^^^^\n  File \"/Users/bill/dev/sdk-samples/SimSelector/dashboard_server.py\", line 1342, in __init__\n    self.phase_manager = get_phase_manager(client)\n                         ^^^^^^^^^^^^^^^^^^^^^^^^^\n  File \"/Users/bill/dev/sdk-samples/SimSelector/phase_manager.py\", line 513, in get_phase_manager\n    _phase_manager = PhaseManager(client)\n                     ^^^^^^^^^^^^^^^^^^^^\n  File \"/Users/bill/dev/sdk-samples/SimSelector/phase_manager.py\", line 83, in __init__\n    self._load_phase_state()\n  File \"/Users/bill/dev/sdk-samples/SimSelector/phase_manager.py\", line 112, in _load_phase_state\n    self._log(f\"Error loading phase state: {str(e)}\", \"ERROR\")\n  File \"/Users/bill/dev/sdk-samples/SimSelector/phase_manager.py\", line 88, in _log\n    self.client.log(f\"PHASE [{level}] {message}\")\n    ^^^^^^^^^^^^^^^\nAttributeError: 'str' object has no attribute 'log'\n"
        },
        {
          "test": "test_security_integration (test_dashboard_server.TestDashboardServer.test_security_integration)",
          "traceback": "Traceback (most recent call last):\n  File \"/Users/bill/anaconda3/lib/python3.12/unittest/mock.py\", line 1395, in patched\n    return func(*newargs, **newkeywargs)\n           ^^^^^^^^^^^^^^^^^^^^^^^^^^^^^\n  File \"/Users/bill/dev/sdk-samples/SimSelector/tests/test_dashboard_server.py\", line 212, in test_security_integration\n    mock_security_manager.validate_ip_access.return_value = SecurityDecision('granted')\n                                                            ^^^^^^^^^^^^^^^^^^^^^^^^^^^\nTypeError: SecurityDecision.__init__() missing 3 required positional arguments: 'client_ip', 'phase_id', and 'timestamp'\n"
        },
        {
          "test": "test_server_lifecycle (test_dashboard_server.TestDashboardServer.test_server_lifecycle)",
          "traceback": "Traceback (most recent call last):\n  File \"/Users/bill/dev/sdk-samples/SimSelector/dashboard_server.py\", line 1395, in start\n    self._log(f\"Dashboard server not started - phase {current_phase} does not allow dashboard access\", \"WARNING\")\n  File \"/Users/bill/dev/sdk-samples/SimSelector/dashboard_server.py\", line 1380, in _log\n    self.client.log(f\"DASHBOARD [{level}] {message}\")\n    ^^^^^^^^^^^^^^^\nAttributeError: 'str' object has no attribute 'log'\n\nDuring handling of the above exception, another exception occurred:\n\nTraceback (most recent call last):\n  File \"/Users/bill/dev/sdk-samples/SimSelector/tests/test_dashboard_server.py\", line 102, in test_server_lifecycle\n    result = self.dashboard_server.start()\n             ^^^^^^^^^^^^^^^^^^^^^^^^^^^^^\n  File \"/Users/bill/dev/sdk-samples/SimSelector/dashboard_server.py\", line 1440, in start\n    self._log(f\"Failed to start dashboard server: {str(e)}\", \"ERROR\")\n  File \"/Users/bill/dev/sdk-samples/SimSelector/dashboard_server.py\", line 1380, in _log\n    self.client.log(f\"DASHBOARD [{level}] {message}\")\n    ^^^^^^^^^^^^^^^\nAttributeError: 'str' object has no attribute 'log'\n"
        }
      ]
    },
    "test_firewall_manager": {
      "tests_run": 6,
      "failures": 0,
      "errors": 0,
      "skipped": 0,
      "success_rate": 100.0,
      "execution_time": 0.00020503997802734375,
      "failure_details": [],
      "error_details": []
    }
  },
  "coverage": {}
}